Workbook

Sheet ACM
A1: CONTROLE DE MATERIAIS - SERRAMBI
A2: LISTA / ATIVIDADE | B2: DESCRIÇÃO DO MATERIAL | C2: QUANTIDADE DA LISTA | D2: DIMENSÕES LARGURA X ALTURA | F2: ÁREA TOTAL | G2: ENTREGA | H2: QUANT. | I2: ENTREGA | J2: QUANT. | K2: ENTREGA | L2: QUANT. | M2: ENTREGA | N2: QUANT. | O2: ÁREA TOTAL RECEBIDA | P2: SALDO DE RECEBIMENTO | Q2: INSTALADO | R2: ÁREA TOTAL INSTALADA | S2: SALDO EM ESTOQUE
A3: ACM | F3: =SUM(D3*E3*C3) -> 0 | O3: =SUM(E3*D3)*(H3+J3) -> 0 | P3: =C3-H3-J3-L3-N3 -> 0 | Q3: 46 | R3: =SUM(D3*E3*(Q3)) -> 0 | S3: =H3+J3+L3+N3-Q3 -> -46
F4: =SUM(D4*E4*C4) -> 0 | O4: =SUM(E4*D4)*(H4+J4) -> 0 | P4: =C4-H4-J4-L4-N4 -> 0 | Q4: 47 | R4: =SUM(D4*E4*(Q4)) -> 0 | S4: =H4+J4+L4+N4-Q4 -> -47
F5: =SUM(D5*E5*C5) -> 0 | O5: =SUM(E5*D5)*(H5+J5) -> 0 | P5: =C5-H5-J5-L5-N5 -> 0 | Q5: 47 | R5: =SUM(D5*E5*(Q5)) -> 0 | S5: =H5+J5+L5+N5-Q5 -> -47
F6: =SUM(D6*E6*C6) -> 0 | O6: =SUM(E6*D6)*(H6+J6) -> 0 | P6: =C6-H6-J6-L6-N6 -> 0 | Q6: 47 | R6: =SUM(D6*E6*(Q6)) -> 0 | S6: =H6+J6+L6+N6-Q6 -> -47
F7: =SUM(D7*E7*C7) -> 0 | O7: =SUM(E7*D7)*(H7+J7) -> 0 | P7: =C7-H7-J7-L7-N7 -> 0 | Q7: 47 | R7: =SUM(D7*E7*(Q7)) -> 0 | S7: =H7+J7+L7+N7-Q7 -> -47
F8: =SUM(D8*E8*C8) -> 0 | O8: =SUM(E8*D8)*(H8+J8) -> 0 | P8: =C8-H8-J8-L8-N8 -> 0 | Q8: 26 | R8: =SUM(D8*E8*(Q8)) -> 0 | S8: =H8+J8+L8+N8-Q8 -> -26
F9: =SUM(D9*E9*C9) -> 0 | O9: =SUM(E9*D9)*(H9+J9) -> 0 | P9: =C9-H9-J9-L9-N9 -> 0 | Q9: 6 | R9: =SUM(D9*E9*(Q9)) -> 0 | S9: =H9+J9+L9+N9-Q9 -> -6
F10: =SUM(D10*E10*C10) -> 0 | O10: =SUM(E10*D10)*(H10+J10) -> 0 | P10: =C10-H10-J10-L10-N10 -> 0 | Q10: 1 | R10: =SUM(D10*E10*(Q10)) -> 0 | S10: =H10+J10+L10+N10-Q10 -> -1
F11: =SUM(D11*E11*C11) -> 0 | O11: =SUM(E11*D11)*(H11+J11) -> 0 | P11: =C11-H11-J11-L11-N11 -> 0 | Q11: 1 | R11: =SUM(D11*E11*(Q11)) -> 0 | S11: =H11+J11+L11+N11-Q11 -> -1
F12: =SUM(D12*E12*C12) -> 0 | O12: =SUM(E12*D12)*(H12+J12) -> 0 | P12: =C12-H12-J12-L12-N12 -> 0 | Q12: 32 | R12: =SUM(D12*E12*(Q12)) -> 0 | S12: =H12+J12+L12+N12-Q12 -> -32
F13: =SUM(D13*E13*C13) -> 0 | O13: =SUM(E13*D13)*(H13+J13) -> 0 | P13: =C13-H13-J13-L13-N13 -> 0 | Q13: 8 | R13: =SUM(D13*E13*(Q13)) -> 0 | S13: =H13+J13+L13+N13-Q13 -> -8
F14: =SUM(D14*E14*C14) -> 0 | O14: =SUM(E14*D14)*(H14+J14) -> 0 | P14: =C14-H14-J14-L14-N14 -> 0 | Q14: 8 | R14: =SUM(D14*E14*(Q14)) -> 0 | S14: =H14+J14+L14+N14-Q14 -> -8
F15: =SUM(D15*E15*C15) -> 0 | O15: =SUM(E15*D15)*(H15+J15+L15+N15) -> 0 | P15: =C15-H15-J15-L15-N15 -> 0 | R15: =SUM(D15*E15*(Q15)) -> 0 | S15: =H15+J15+L15+N15-Q15 -> 0
F16: =SUM(D16*E16*C16) -> 0 | O16: =SUM(E16*D16)*(H16+J16+L16+N16) -> 0 | P16: =C16-H16-J16-L16-N16 -> 0 | R16: =SUM(D16*E16*(Q16)) -> 0 | S16: =H16+J16+L16+N16-Q16 -> 0
F17: =SUM(D17*E17*C17) -> 0 | O17: =SUM(E17*D17)*(H17+J17+L17+N17) -> 0 | P17: =C17-H17-J17-L17-N17 -> 0 | R17: =SUM(D17*E17*(Q17)) -> 0 | S17: =H17+J17+L17+N17-Q17 -> 0
F18: =SUM(D18*E18*C18) -> 0 | O18: =SUM(E18*D18)*(H18+J18+L18+N18) -> 0 | P18: =C18-H18-J18-L18-N18 -> 0 | R18: =SUM(D18*E18*(Q18)) -> 0 | S18: =H18+J18+L18+N18-Q18 -> 0
F19: =SUM(D19*E19*C19) -> 0 | O19: =SUM(E19*D19)*(H19+J19+L19+N19) -> 0 | P19: =C19-H19-J19-L19-N19 -> 0 | R19: =SUM(D19*E19*(Q19)) -> 0 | S19: =H19+J19+L19+N19-Q19 -> 0
F20: =SUM(D20*E20*C20) -> 0 | O20: =SUM(E20*D20)*(H20+J20+L20+N20) -> 0 | P20: =C20-H20-J20-L20-N20 -> 0 | R20: =SUM(D20*E20*(Q20)) -> 0 | S20: =H20+J20+L20+N20-Q20 -> 0
F21: =SUM(D21*E21*C21) -> 0 | O21: =SUM(E21*D21)*(H21+J21+L21+N21) -> 0 | P21: =C21-H21-J21-L21-N21 -> 0 | R21: =SUM(D21*E21*(Q21)) -> 0 | S21: =H21+J21+L21+N21-Q21 -> 0
F22: =SUM(D22*E22*C22) -> 0 | O22: =SUM(E22*D22)*(H22+J22+L22+N22) -> 0 | P22: =C22-H22-J22-L22-N22 -> 0 | R22: =SUM(D22*E22*(Q22)) -> 0 | S22: =H22+J22+L22+N22-Q22 -> 0
F23: =SUM(D23*E23*C23) -> 0 | O23: =SUM(E23*D23)*(H23+J23+L23+N23) -> 0 | P23: =C23-H23-J23-L23-N23 -> 0 | R23: =SUM(D23*E23*(Q23)) -> 0 | S23: =H23+J23+L23+N23-Q23 -> 0
F24: =SUM(D24*E24*C24) -> 0 | O24: =SUM(E24*D24)*(H24+J24+L24+N24) -> 0 | P24: =C24-H24-J24-L24-N24 -> 0 | R24: =SUM(D24*E24*(Q24)) -> 0 | S24: =H24+J24+L24+N24-Q24 -> 0
F25: =SUM(D25*E25*C25) -> 0 | O25: =SUM(E25*D25)*(H25+J25+L25+N25) -> 0 | P25: =C25-H25-J25-L25-N25 -> 0 | R25: =SUM(D25*E25*(Q25)) -> 0 | S25: =H25+J25+L25+N25-Q25 -> 0
F26: =SUM(D26*E26*C26) -> 0 | O26: =SUM(E26*D26)*(H26+J26+L26+N26) -> 0 | P26: =C26-H26-J26-L26-N26 -> 0 | R26: =SUM(D26*E26*(Q26)) -> 0 | S26: =H26+J26+L26+N26-Q26 -> 0
... F57: =SUM(D57*E57*C57) -> 0 | O57: =SUM(E57*D57)*(H57+J57+L57+N57) -> 0 | P57: =C57-H57-J57-L57-N57 -> 0 | R57: =SUM(D57*E57*(Q57)) -> 0 | S57: =H57+J57+L57+N57-Q57 -> 0
O58: =SUM(E58*D58)*(H58+J58+L58+N58) -> 0 | P58: =C58-H58-J58-L58-N58 -> 0 | R58: =SUM(D58*E58*(Q58)) -> 0 | S58: =H58+J58+L58+N58-Q58 -> 0
O59: =SUM(E59*D59)*(H59+J59+L59+N59) -> 0 | P59: =C59-H59-J59-L59-N59 -> 0 | R59: =SUM(D59*E59*(Q59)) -> 0 | S59: =H59+J59+L59+N59-Q59 -> 0
O60: =SUM(E60*D60)*(H60+J60+L60+N60) -> 0 | P60: =C60-H60-J60-L60-N60 -> 0 | R60: =SUM(D60*E60*(Q60)) -> 0 | S60: =H60+J60+L60+N60-Q60 -> 0
O61: =SUM(E61*D61)*(H61+J61+L61+N61) -> 0 | P61: =C61-H61-J61-L61-N61 -> 0 | R61: =SUM(D61*E61*(Q61)) -> 0 | S61: =H61+J61+L61+N61-Q61 -> 0
O62: =SUM(E62*D62)*(H62+J62+L62+N62) -> 0 | P62: =C62-H62-J62-L62-N62 -> 0 | R62: =SUM(D62*E62*(Q62)) -> 0 | S62: =H62+J62+L62+N62-Q62 -> 0
O63: =SUM(E63*D63)*(H63+J63+L63+N63) -> 0 | P63: =C63-H63-J63-L63-N63 -> 0 | R63: =SUM(D63*E63*(Q63)) -> 0 | S63: =H63+J63+L63+N63-Q63 -> 0
O64: =SUM(E64*D64)*(H64+J64+L64+N64) -> 0 | P64: =C64-H64-J64-L64-N64 -> 0 | R64: =SUM(D64*E64*(Q64)) -> 0 | S64: =H64+J64+L64+N64-Q64 -> 0
O65: =SUM(E65*D65)*(H65+J65+L65+N65) -> 0 | P65: =C65-H65-J65-L65-N65 -> 0 | R65: =SUM(D65*E65*(Q65)) -> 0 | S65: =H65+J65+L65+N65-Q65 -> 0
O66: =SUM(E66*D66)*(H66+J66+L66+N66) -> 0 | P66: =C66-H66-J66-L66-N66 -> 0 | R66: =SUM(D66*E66*(Q66)) -> 0 | S66: =H66+J66+L66+N66-Q66 -> 0
O67: =SUM(E67*D67)*(H67+J67+L67+N67) -> 0 | P67: =C67-H67-J67-L67-N67 -> 0 | R67: =SUM(D67*E67*(Q67)) -> 0 | S67: =H67+J67+L67+N67-Q67 -> 0
O68: =SUM(E68*D68)*(H68+J68+L68+N68) -> 0 | P68: =C68-H68-J68-L68-N68 -> 0 | R68: =SUM(D68*E68*(Q68)) -> 0 | S68: =H68+J68+L68+N68-Q68 -> 0
O69: =SUM(E69*D69)*(H69+J69+L69+N69) -> 0 | P69: =C69-H69-J69-L69-N69 -> 0 | R69: =SUM(D69*E69*(Q69)) -> 0 | S69: =H69+J69+L69+N69-Q69 -> 0
... O86: =SUM(E86*D86)*(H86+J86+L86+N86) -> 0 | P86: =C86-H86-J86-L86-N86 -> 0 | R86: =SUM(D86*E86*(Q86)) -> 0 | S86: =H86+J86+L86+N86-Q86 -> 0
...

Sheet GUADA CORPO
A1: CONTROLE DE OBRA - MAHRAK VILLA
A2: LISTA / ATIVIDADE | B2: REFERÊNCIA | C2: TIPOLOGIA | D2: LOCALIZAÇÃO | E2: QUANTIDADE DA LISTA | F2: DIMENSÕES LARGURA X ALTURA | H2: ÁREA TOTAL | I2: ENTREGA | J2: QUANT. | K2: ENTREGA | L2: QUANT. | M2: ENTREGA | N2: QUANT. | O2: ÁREA TOTAL RECEBIDA | P2: SALDO DE RECEBIMENTO | Q2: INSTALADO | R2: ÁREA TOTAL INSTALADA | S2: SALDO EM ESTOQUE
H3: =SUM(F3*G3*E3) -> 0 | O3: =SUM(F3*G3*(J3+L3+N3)) -> 0 | P3: =E3-J3-L3-N3 -> 0 | R3: =SUM(F3*G3*(Q3)) -> 0 | S3: =J3+L3+N3-Q3 -> 0
H4: =SUM(F4*G4*E4) -> 0 | O4: =SUM(F4*G4*(J4+L4+N4)) -> 0 | P4: =E4-J4-L4-N4 -> 0 | R4: =SUM(F4*G4*(Q4)) -> 0 | S4: =J4+L4+N4-Q4 -> 0
H5: =SUM(F5*G5*E5) -> 0 | O5: =SUM(F5*G5*(J5+L5+N5)) -> 0 | P5: =E5-J5-L5-N5 -> 0 | R5: =SUM(F5*G5*(Q5)) -> 0 | S5: =J5+L5+N5-Q5 -> 0
H6: =SUM(F6*G6*E6) -> 0 | O6: =SUM(F6*G6*(J6+L6+N6)) -> 0 | P6: =E6-J6-L6-N6 -> 0 | R6: =SUM(F6*G6*(Q6)) -> 0 | S6: =J6+L6+N6-Q6 -> 0
H7: =SUM(F7*G7*E7) -> 0 | O7: =SUM(F7*G7*(J7+L7+N7)) -> 0 | P7: =E7-J7-L7-N7 -> 0 | R7: =SUM(F7*G7*(Q7)) -> 0 | S7: =J7+L7+N7-Q7 -> 0
H8: =SUM(F8*G8*E8) -> 0 | O8: =SUM(F8*G8*(J8+L8+N8)) -> 0 | P8: =E8-J8-L8-N8 -> 0 | R8: =SUM(F8*G8*(Q8)) -> 0 | S8: =J8+L8+N8-Q8 -> 0
H9: =SUM(F9*G9*E9) -> 0 | O9: =SUM(F9*G9*(J9+L9+N9)) -> 0 | P9: =E9-J9-L9-N9 -> 0 | R9: =SUM(F9*G9*(Q9)) -> 0 | S9: =J9+L9+N9-Q9 -> 0
H10: =SUM(F10*G10*E10) -> 0 | O10: =SUM(F10*G10*(J10+L10+N10)) -> 0 | P10: =E10-J10-L10-N10 -> 0 | R10: =SUM(F10*G10*(Q10)) -> 0 | S10: =J10+L10+N10-Q10 -> 0
H11: =SUM(F11*G11*E11) -> 0 | O11: =SUM(F11*G11*(J11+L11+N11)) -> 0 | P11: =E11-J11-L11-N11 -> 0 | R11: =SUM(F11*G11*(Q11)) -> 0 | S11: =J11+L11+N11-Q11 -> 0
H12: =SUM(F12*G12*E12) -> 0 | O12: =SUM(F12*G12*(J12+L12+N12)) -> 0 | P12: =E12-J12-L12-N12 -> 0 | R12: =SUM(F12*G12*(Q12)) -> 0 | S12: =J12+L12+N12-Q12 -> 0
H13: =SUM(F13*G13*E13) -> 0 | O13: =SUM(F13*G13*(J13+L13+N13)) -> 0 | P13: =E13-J13-L13-N13 -> 0 | R13: =SUM(F13*G13*(Q13)) -> 0 | S13: =J13+L13+N13-Q13 -> 0
H14: =SUM(F14*G14*E14) -> 0 | O14: =SUM(F14*G14*(J14+L14+N14)) -> 0 | P14: =E14-J14-L14-N14 -> 0 | R14: =SUM(F14*G14*(Q14)) -> 0 | S14: =J14+L14+N14-Q14 -> 0
H15: =SUM(F15*G15*E15) -> 0 | O15: =SUM(F15*G15*(J15+L15+N15)) -> 0 | P15: =E15-J15-L15-N15 -> 0 | R15: =SUM(F15*G15*(Q15)) -> 0 | S15: =J15+L15+N15-Q15 -> 0
H16: =SUM(F16*G16*E16) -> 0

Sheet GRADIL
A1: CONTROLE DE OBRA - MAHRAK VILLA
A2: LISTA / ATIVIDADE | B2: REFERÊNCIA | C2: TIPOLOGIA | D2: LOCALIZAÇÃO | E2: QUANTIDADE DA LISTA | F2: DIMENSÕES LARGURA X ALTURA | H2: ÁREA TOTAL | I2: ENTREGA | J2: QUANT. | K2: ENTREGA | L2: QUANT. | M2: ENTREGA | N2: QUANT. | O2: SALDO DE RECEBIMENTO | P2: INSTALADO | Q2: ÁREA TOTAL INSTALADA | R2: SALDO EM ESTOQUE
H3: =SUM(F3*G3*E3) -> 0 | O3: =E3-J3-L3-N3 -> 0 | Q3: =SUM(F3*G3*(P3)) -> 0 | R3: =J3+L3+N3-P3 -> 0
H4: =SUM(F4*G4*E4) -> 0 | O4: =E4-J4-L4-N4 -> 0 | Q4: =SUM(F4*G4*(P4)) -> 0 | R4: =J4+L4+N4-P4 -> 0
H5: =SUM(F5*G5*E5) -> 0 | O5: =E5-J5-L5-N5 -> 0 | Q5: =SUM(F5*G5*(P5)) -> 0 | R5: =J5+L5+N5-P5 -> 0
H6: =SUM(F6*G6*E6) -> 0 | O6: =E6-J6-L6-N6 -> 0 | Q6: =SUM(F6*G6*(P6)) -> 0 | R6: =J6+L6+N6-P6 -> 0
H7: =SUM(F7*G7*E7) -> 0 | O7: =E7-J7-L7-N7 -> 0 | Q7: =SUM(F7*G7*(P7)) -> 0 | R7: =J7+L7+N7-P7 -> 0
H8: =SUM(F8*G8*E8) -> 0 | O8: =E8-J8-L8-N8 -> 0 | Q8: =SUM(F8*G8*(P8)) -> 0 | R8: =J8+L8+N8-P8 -> 0
H9: =SUM(F9*G9*E9) -> 0 | O9: =E9-J9-L9-N9 -> 0 | Q9: =SUM(F9*G9*(P9)) -> 0 | R9: =J9+L9+N9-P9 -> 0
H10: =SUM(F10*G10*E10) -> 0 | O10: =E10-J10-L10-N10 -> 0 | Q10: =SUM(F10*G10*(P10)) -> 0 | R10: =J10+L10+N10-P10 -> 0
H11: =SUM(F11*G11*E11) -> 0 | O11: =E11-J11-L11-N11 -> 0 | Q11: =SUM(F11*G11*(P11)) -> 0 | R11: =J11+L11+N11-P11 -> 0
H12: =SUM(F12*G12*E12) -> 0 | O12: =E12-J12-L12-N12 -> 0 | Q12: =SUM(F12*G12*(P12)) -> 0 | R12: =J12+L12+N12-P12 -> 0
H13: =SUM(F13*G13*E13) -> 0 | O13: =E13-J13-L13-N13 -> 0 | Q13: =SUM(F13*G13*(P13)) -> 0 | R13: =J13+L13+N13-P13 -> 0
H14: =SUM(F14*G14*E14) -> 0 | O14: =E14-J14-L14-N14 -> 0 | Q14: =SUM(F14*G14*(P14)) -> 0 | R14: =J14+L14+N14-P14 -> 0
H15: =SUM(F15*G15*E15) -> 0 | O15: =E15-J15-L15-N15 -> 0 | Q15: =SUM(F15*G15*(P15)) -> 0 | R15: =J15+L15+N15-P15 -> 0

Sheet PORTA E JANELA
A1: BURJ LAVIE
A2: REFERÊNCIA | B2: TIPOLOGIA | C2: LOCALIZAÇÃO | D2: QUANTIDADE DO CONTRATO | E2: DIMENSÕES LARGURA X ALTURA | G2: ÁREA TOTAL | H2: ENTREGA | I2: QUANT. | J2: ENTREGA | K2: QUANT. | L2: ENTREGA | M2: QUANT. | N2: ÁREA TOTAL RECEBIDA | O2: SALDO DE RECEBIMENTO | P2: INSTALADO | Q2: ÁREA TOTAL INSTALADA | R2: SALDO EM ESTOQUE
G3: =SUM(E3*F3*D3) -> 0 | N3: =SUM(E3*F3*(I3+K3+M3)) -> 0 | O3: =D3-I3-K3-M3 -> 0 | Q3: =SUM(E3*F3*(P3)) -> 0 | R3: =I3+K3+M3-P3 -> 0
G4: =SUM(E4*F4*D4) -> 0 | N4: =SUM(E4*F4*(I4+K4+M4)) -> 0 | O4: =D4-I4-K4-M4 -> 0 | Q4: =SUM(E4*F4*(P4)) -> 0 | R4: =I4+K4+M4-P4 -> 0
G5: =SUM(E5*F5*D5) -> 0 | N5: =SUM(E5*F5*(I5+K5+M5)) -> 0 | O5: =D5-I5-K5-M5 -> 0 | Q5: =SUM(E5*F5*(P5)) -> 0 | R5: =I5+K5+M5-P5 -> 0
G6: =SUM(E6*F6*D6) -> 0 | N6: =SUM(E6*F6*(I6+K6+M6)) -> 0 | O6: =D6-I6-K6-M6 -> 0 | Q6: =SUM(E6*F6*(P6)) -> 0 | R6: =I6+K6+M6-P6 -> 0
G7: =SUM(E7*F7*D7) -> 0 | N7: =SUM(E7*F7*(I7+K7+M7)) -> 0 | O7: =D7-I7-K7-M7 -> 0 | Q7: =SUM(E7*F7*(P7)) -> 0 | R7: =I7+K7+M7-P7 -> 0
G8: =SUM(E8*F8*D8) -> 0 | N8: =SUM(E8*F8*(I8+K8+M8)) -> 0 | O8: =D8-I8-K8-M8 -> 0 | Q8: =SUM(E8*F8*(P8)) -> 0 | R8: =I8+K8+M8-P8 -> 0
G9: =SUM(E9*F9*D9) -> 0 | N9: =SUM(E9*F9*(I9+K9+M9)) -> 0 | O9: =D9-I9-K9-M9 -> 0 | Q9: =SUM(E9*F9*(P9)) -> 0 | R9: =I9+K9+M9-P9 -> 0
G10: =SUM(E10*F10*D10) -> 0 | N10: =SUM(E10*F10*(I10+K10+M10)) -> 0 | O10: =D10-I10-K10-M10 -> 0 | Q10: =SUM(E10*F10*(P10)) -> 0 | R10: =I10+K10+M10-P10 -> 0
G11: =SUM(E11*F11*D11) -> 0 | N11: =SUM(E11*F11*(I11+K11+M11)) -> 0 | O11: =D11-I11-K11-M11 -> 0 | Q11: =SUM(E11*F11*(P11)) -> 0 | R11: =I11+K11+M11-P11 -> 0
G12: =SUM(E12*F12*D12) -> 0 | N12: =SUM(E12*F12*(I12+K12+M12)) -> 0 | O12: =D12-I12-K12-M12 -> 0 | Q12: =SUM(E12*F12*(P12)) -> 0 | R12: =I12+K12+M12-P12 -> 0
G13: =SUM(E13*F13*D13) -> 0 | N13: =SUM(E13*F13*(I13+K13+M13)) -> 0 | O13: =D13-I13-K13-M13 -> 0 | Q13: =SUM(E13*F13*(P13)) -> 0 | R13: =I13+K13+M13-P13 -> 0
G14: =SUM(E14*F14*D14) -> 0 | N14: =SUM(E14*F14*(I14+K14+M14)) -> 0 | O14: =D14-I14-K14-M14 -> 0 | Q14: =SUM(E14*F14*(P14)) -> 0 | R14: =I14+K14+M14-P14 -> 0
G15: =SUM(E15*F15*D15) -> 0 | O15: =D15-I15-K15-M15 -> 0
G16: =SUM(E16*F16*D16) -> 0 | N16: =SUM(E16*F16*(I16+K16+M16)) -> 0 | O16: =D16-I16-K16-M16 -> 0 | Q16: =SUM(E16*F16*(P16)) -> 0 | R16: =I16+K16+M16-P16 -> 0
G17: =SUM(E17*F17*D17) -> 0 | N17: =SUM(E17*F17*(I17+K17+M17)) -> 0 | O17: =D17-I17-K17-M17 -> 0 | Q17: =SUM(E17*F17*(P17)) -> 0 | R17: =I17+K17+M17-P17 -> 0
G18: =SUM(E18*F18*D18) -> 0 | N18: =SUM(E18*F18*(I18+K18+M18)) -> 0 | O18: =D18-I18-K18-M18 -> 0 | Q18: =SUM(E18*F18*(P18)) -> 0 | R18: =I18+K18+M18-P18 -> 0
G19: =SUM(E19*F19*D19) -> 0 | N19: =SUM(E19*F19*(I19+K19+M19)) -> 0 | O19: =D19-I19-K19-M19 -> 0 | Q19: =SUM(E19*F19*(P19)) -> 0 | R19: =I19+K19+M19-P19 -> 0
G20: =SUM(E20*F20*D20) -> 0 | N20: =SUM(E20*F20*(I20+K20+M20)) -> 0 | O20: =D20-I20-K20-M20 -> 0 | Q20: =SUM(E20*F20*(P20)) -> 0 | R20: =I20+K20+M20-P20 -> 0
G21: =SUM(E21*F21*D21) -> 0 | N21: =SUM(E21*F21*(I21+K21+M21)) -> 0 | O21: =D21-I21-K21-M21 -> 0 | Q21: =SUM(E21*F21*(P21)) -> 0 | R21: =I21+K21+M21-P21 -> 0
G22: =SUM(E22*F22*D22) -> 0 | N22: =SUM(E22*F22*(I22+K22+M22)) -> 0 | O22: =D22-I22-K22-M22 -> 0 | Q22: =SUM(E22*F22*(P22)) -> 0 | R22: =I22+K22+M22-P22 -> 0
G23: =SUM(E23*F23*D23) -> 0 | N23: =SUM(E23*F23*(I23+K23+M23)) -> 0 | O23: =D23-I23-K23-M23 -> 0 | Q23: =SUM(E23*F23*(P23)) -> 0 | R23: =I23+K23+M23-P23 -> 0
G24: =SUM(E24*F24*D24) -> 0 | N24: =SUM(E24*F24*(I24+K24+M24)) -> 0 | O24: =D24-I24-K24-M24 -> 0 | Q24: =SUM(E24*F24*(P24)) -> 0 | R24: =I24+K24+M24-P24 -> 0

Sheet PELE DE VIDRO
A1: CONTROLE DE OBRA - BURJ LAVIE
A2: LISTA / ATIVIDADE | B2: REFERÊNCIA | C2: TIPOLOGIA | D2: LOCALIZAÇÃO | E2: QUANTIDADE DA LISTA | F2: DIMENSÕES LARGURA X ALTURA | H2: ÁREA TOTAL M² | I2: ENTREGA | J2: QUANT. | K2: ENTREGA | L2: QUANT. | M2: ENTREGA | N2: QUANT. | O2: ENTREGA | P2: QUANT. | Q2: ENTREGA | R2: QUANT. | S2: TOTAL RECEBEDO | T2: SALDO DE RECEBIMENTO | U2: INSTALADO | V2: ÁREA TOTAL INSTALADA M² | W2: SALDO EM ESTOQUE
A3: P-76D-24 LOTE 01 = 321 QUADROS | B3: J05 - LOTE 1 | C3: Modulo de fachada fixo c/ vidro lote 1 | D3: Pav. Tipo do 2º ao 14 | E3: 108 | F3: 0.86666 | G3: 2.8 | H3: =SUM(F3*G3*E3) -> 262.07798 | I3: 46037 | J3: 21 | K3: 46043 | L3: 14 | M3: 46049 | N3: 19 | O3: 46056 | P3: 7 | S3: =SUM(J3+L3+N3+P3+R3) -> 61 | T3: =E3-J3-L3-N3-P3-R3 -> 47 | U3: 47 | V3: =SUM(F3*G3*(U3)) -> 114.05246 | W3: =SUM(J3+L3+N3+P3+R3-U3) -> 14
B4: J05-QD02 | C4: Modulo de fachada maxim-ar c/ vidro | D4: Pav. Tipo do 2º ao 14 | E4: 108 | F4: 0.86667 | G4: 2.8 | H4: =SUM(F4*G4*E4) -> 262.08101 | I4: 46037 | J4: 25 | K4: 46043 | L4: 17 | M4: 46049 | N4: 18 | O4: 46056 | P4: 13 | S4: =SUM(J4+L4+N4+P4+R4) -> 73 | T4: =E4-J4-L4-N4-P4-R4 -> 35 | U4: 47 | V4: =SUM(F4*G4*(U4)) -> 114.05377 | W4: =J4+L4+N4+P4+R4-U4 -> 26
B5: J05-QD03 | C5: Modulo de fachada fixo c/ vidro | D5: Pav. Tipo do 2º ao 14 | E5: 108 | F5: 0.86667 | G5: 2.8 | H5: =SUM(F5*G5*E5) -> 262.08101 | I5: 46037 | J5: 16 | K5: 46043 | L5: 10 | M5: 46049 | N5: 28 | O5: 46056 | P5: 6 | S5: =SUM(J5+L5+P5+N5+R5) -> 60 | T5: =E5-J5-L5-N5-P5-R5 -> 48 | U5: 47 | V5: =SUM(F5*G5*(U5)) -> 114.05377 | W5: =J5+L5+N5+P5+R5-U5 -> 13
A6: P-76E-24 LOTE 02 = 321 QUADROS | B6: J05 - LOTE 2 | C6: Modulo de fachada fixo c/ vidro | D6: Pav. Tipo do 2º ao 14 | E6: 108 | F6: 0.86666 | G6: 2.8 | H6: =SUM(F6*G6*E6) -> 262.07798 | T6: =E6-J6-L6-N6 -> 108 | V6: =SUM(F6*G6*(U6)) -> 0 | W6: =J6+L6+N6-U6 -> 0
B7: J05-QD02 | C7: Modulo de fachada maxim-ar c/ vidro | D7: Pav. Tipo do 2º ao 14 | E7: 108 | F7: 0.86667 | G7: 2.8 | H7: =SUM(F7*G7*E7) -> 262.08101 | T7: =E7-J7-L7-N7 -> 108 | V7: =SUM(F7*G7*(U7)) -> 0 | W7: =J7+L7+N7-U7 -> 0
B8: J05-QD03 | C8: Modulo de fachada fixo c/ vidro | D8: Pav. Tipo do 2º ao 14 | E8: 108 | F8: 0.86667 | G8: 2.8 | H8: =SUM(F8*G8*E8) -> 262.08101 | T8: =E8-J8-L8-N8 -> 108 | V8: =SUM(F8*G8*(U8)) -> 0 | W8: =J8+L8+N8-U8 -> 0
H9: =SUM(F9*G9*E9) -> 0 | T9: =E9-J9-L9-N9 -> 0 | V9: =SUM(F9*G9*(U9)) -> 0 | W9: =J9+L9+N9-U9 -> 0
H10: =SUM(F10*G10*E10) -> 0 | T10: =E10-J10-L10-N10 -> 0 | V10: =SUM(F10*G10*(U10)) -> 0 | W10: =J10+L10+N10-U10 -> 0
H11: =SUM(F11*G11*E11) -> 0 | U11: =SUM(U3:U5)/3 -> 47 | V11: =SUM(V3:V5)/3 -> 114.05333

Sheet CONTROLE DE OBRA BURJ LAVIE
A1: CONTROLE DE OBRA - BURJ LAVIE
A2: Referência | B2: Tipologia | C2: Localização | D2: Quantidade | E2: Largura | F2: Altura | G2: Área Total | H2: FEM | I2: Saldo | J2: % | K2: Fabricado | L2: Saldo | M2: % | N2: Instalado | O2: M² Instalado | P2: M² Saldo | Q2: %
A3: ='PELE DE VIDRO'!B3 -> J05 - LOTE 1 | B3: Fachada pele de vidro entre vãos c/ 3 modulos em parte fixas e moveis lote 1 | C3: ='PELE DE VIDRO'!D3 -> Pav. Tipo do 2º ao 14 | D3: =SUM('PELE DE VIDRO'!E3:E5)/3 -> 108 | E3: ='PELE DE VIDRO'!F3*3 -> 2.59998 | F3: ='PELE DE VIDRO'!G3 -> 2.8 | G3: =SUM(E3*F3*D3) -> 786.23395 | H3: =SUM(D3) -> 108 | I3: =H3-D3 -> 0 | J3: =H3/H3 -> 1 | K3: =SUM('PELE DE VIDRO'!S3:S5)/3 -> 64.666667 | L3: =H3-K3 -> 43.333333 | M3: =K3/D3 -> 0.59876543 | N3: =SUM('PELE DE VIDRO'!U3:U5)/3 -> 47 | O3: =SUM(E3*F3*N3) -> 342.15737 | P3: =G3-O3 -> 444.07658 | Q3: =SUM(O3/G3) -> 0.43518519
A4: ='PELE DE VIDRO'!B6 -> J05 - LOTE 2 | B4: Fachada pele de vidro entre vãos c/ 3 modulos em parte fixas e moveis lote 2 | C4: ='PELE DE VIDRO'!D6 -> Pav. Tipo do 2º ao 14 | D4: =SUM('PELE DE VIDRO'!E6:E8)/3 -> 108 | E4: ='PELE DE VIDRO'!F6*3 -> 2.59998 | F4: ='PELE DE VIDRO'!G6 -> 2.8 | G4: =SUM(E4*F4*D4) -> 786.23395 | H4: =D4 -> 108 | I4: =D4-H4 -> 0 | J4: =H4/H4 -> 1 | K4: =SUM('PELE DE VIDRO'!S6:S8)/3 -> 0 | L4: =H4-K4 -> 108 | M4: =K4/D4 -> 0 | N4: =SUM('PELE DE VIDRO'!U6:U8)/3 -> 0 | O4: =SUM(E4*F4*N4) -> 0 | P4: =G4-O4 -> 786.23395 | Q4: =O4/G4 -> 0
A36: Resumo | D36: =SUM(D3:D35) -> 216 | G36: =SUM(G3:G35) -> 1572.4679 | H36: =SUM(H3:H35) -> 216 | I36: =D36-H36 -> 0 | J36: =H36/D36 -> 1 | K36: =SUM(K3:K35) -> 64.666667 | L36: =SUM(L3:L35) -> 151.33333 | M36: =K36/D36 -> 0.29938272 | N36: =SUM(N3:N35) -> 47 | O36: =SUM(O3:O35) -> 342.15737 | P36: =SUM(P3:P35) -> 1230.3105 | Q36: =O36/G36 -> 0.21759259

Sheet 1º MEDIÇÃO
A1: CONTROLE DE MEDIÇÃO - BURJ LAVIE
A2: M² Total: | B2: =SUM(E5:E35) -> 1572.48 | C2: Medição Instalação Total: | D2: 140000 | E2: M² Realizado Acumulado: | F2: 152.88 | G2: Medição Acumulado: | H2: 12930.46 | J2: Medição Nº: | K2: 2
D3: 1043756.4 | E3: M² Realizado Atual: | F3: =SUM(F5:F36)-(F2) -> 189.27737 | G3: Medição Atual com Retenção: | H3: =SUM(J5:J36)-(H2) -> 16009.132
A4: Referência | B4: Tipologia | C4: Localização | D4: Quantidade | E4: Área Total M² | F4: Realizado M² | G4: Saldo M² | H4: Medição Contrato | I4: Medição Realizado Total | J4: Medição com Retenção de 5% | K4: Saldo Medição
A5: ='CONTROLE DE OBRA BURJ LAVIE'!A3 -> J05 - LOTE 1 | B5: ='CONTROLE DE OBRA BURJ LAVIE'!B3 -> Fachada pele de vidro entre vãos c/ 3 modulos em parte fixas e moveis lote 1 | C5: ='CONTROLE DE OBRA BURJ LAVIE'!C3 -> Pav. Tipo do 2º ao 14 | D5: ='PELE DE VIDRO'!U3 -> 47 | E5: =SUM('PELE DE VIDRO'!H3:H5) -> 786.24 | F5: ='CONTROLE DE OBRA BURJ LAVIE'!O3 -> 342.15737 | G5: =E5-F5 -> 444.08263 | H5: =E5/$B$2*$D$2 -> 70000 | I5: =F5/$B$2*$D$2 -> 30462.729 | J5: =(F5/$B$2*$D$2)*(95%) -> 28939.592 | K5: =H5-J5 -> 41060.408
A6: ='CONTROLE DE OBRA BURJ LAVIE'!A4 -> J05 - LOTE 2 | B6: ='CONTROLE DE OBRA BURJ LAVIE'!B4 -> Fachada pele de vidro entre vãos c/ 3 modulos em parte fixas e moveis lote 2 | C6: ='CONTROLE DE OBRA BURJ LAVIE'!C4 -> Pav. Tipo do 2º ao 14 | D6: ='PELE DE VIDRO'!U6 -> 0 | E6: =SUM('PELE DE VIDRO'!H4:H6) -> 786.24 | F6: ='CONTROLE DE OBRA BURJ LAVIE'!O4 -> 0 | G6: =E6-F6 -> 786.24 | H6: =E6/$B$2*$D$2 -> 70000 | I6: =F6/$B$2*$D$2 -> 0 | J6: =(F6/$B$2*$D$2)*(95%) -> 0 | K6: =H6-J6 -> 70000
F7: ='CONTROLE DE OBRA BURJ LAVIE'!O5 -> 0 | G7: =E7-F7 -> 0 | H7: =E7/$B$2*$D$2 -> 0 | I7: =F7/$B$2*$D$2 -> 0 | J7: =(F7/$B$2*$D$2)*(95%) -> 0 | K7: =H7-J7 -> 0
F8: ='CONTROLE DE OBRA BURJ LAVIE'!O6 -> 0 | G8: =E8-F8 -> 0 | H8: =E8/$B$2*$D$2 -> 0 | I8: =F8/$B$2*$D$2 -> 0 | J8: =(F8/$B$2*$D$2)*(95%) -> 0 | K8: =H8-J8 -> 0
F9: ='CONTROLE DE OBRA BURJ LAVIE'!O7 -> 0 | G9: =E9-F9 -> 0 | H9: =E9/$B$2*$D$2 -> 0 | I9: =F9/$B$2*$D$2 -> 0 | J9: =(F9/$B$2*$D$2)*(95%) -> 0 | K9: =H9-J9 -> 0
F10: ='CONTROLE DE OBRA BURJ LAVIE'!O8 -> 0 | G10: =E10-F10 -> 0 | H10: =E10/$B$2*$D$2 -> 0 | I10: =F10/$B$2*$D$2 -> 0 | J10: =(F10/$B$2*$D$2)*(95%) -> 0 | K10: =H10-J10 -> 0
F11: ='CONTROLE DE OBRA BURJ LAVIE'!O9 -> 0 | G11: =E11-F11 -> 0 | H11: =E11/$B$2*$D$2 -> 0 | I11: =F11/$B$2*$D$2 -> 0 | J11: =(F11/$B$2*$D$2)*(95%) -> 0 | K11: =H11-J11 -> 0
F12: ='CONTROLE DE OBRA BURJ LAVIE'!O10 -> 0 | G12: =E12-F12 -> 0 | H12: =E12/$B$2*$D$2 -> 0 | I12: =F12/$B$2*$D$2 -> 0 | J12: =(F12/$B$2*$D$2)*(95%) -> 0 | K12: =H12-J12 -> 0
F13: ='CONTROLE DE OBRA BURJ LAVIE'!O11 -> 0 | G13: =E13-F13 -> 0 | H13: =E13/$B$2*$D$2 -> 0 | I13: =F13/$B$2*$D$2 -> 0 | J13: =(F13/$B$2*$D$2)*(95%) -> 0 | K13: =H13-J13 -> 0
F14: ='CONTROLE DE OBRA BURJ LAVIE'!O12 -> 0 | G14: =E14-F14 -> 0 | H14: =E14/$B$2*$D$2 -> 0 | I14: =F14/$B$2*$D$2 -> 0 | J14: =(F14/$B$2*$D$2)*(95%) -> 0 | K14: =H14-J14 -> 0
F15: ='CONTROLE DE OBRA BURJ LAVIE'!O13 -> 0 | G15: =E15-F15 -> 0 | H15: =E15/$B$2*$D$2 -> 0 | I15: =F15/$B$2*$D$2 -> 0 | J15: =(F15/$B$2*$D$2)*(95%) -> 0 | K15: =H15-J15 -> 0
F16: ='CONTROLE DE OBRA BURJ LAVIE'!O14 -> 0 | G16: =E16-F16 -> 0 | H16: =E16/$B$2*$D$2 -> 0 | I16: =F16/$B$2*$D$2 -> 0 | J16: =(F16/$B$2*$D$2)*(95%) -> 0 | K16: =H16-J16 -> 0
F17: ='CONTROLE DE OBRA BURJ LAVIE'!O15 -> 0 | G17: =E17-F17 -> 0 | H17: =E17/$B$2*$D$2 -> 0 | I17: =F17/$B$2*$D$2 -> 0 | J17: =(F17/$B$2*$D$2)*(95%) -> 0 | K17: =H17-J17 -> 0
F18: ='CONTROLE DE OBRA BURJ LAVIE'!O16 -> 0 | G18: =E18-F18 -> 0 | H18: =E18/$B$2*$D$2 -> 0 | I18: =F18/$B$2*$D$2 -> 0 | J18: =(F18/$B$2*$D$2)*(95%) -> 0 | K18: =H18-J18 -> 0
... F35: ='CONTROLE DE OBRA BURJ LAVIE'!O33 -> 0 | G35: =E35-F35 -> 0 | H35: =E35/$B$2*$D$2 -> 0 | I35: =F35/$B$2*$D$2 -> 0 | J35: =(F35/$B$2*$D$2)*(95%) -> 0 | K35: =H35-J35 -> 0
E36: =SUM(E5:E35) -> 1572.48
A38: Considerações Medição
A39: Instalação de Pele de vidro entre vãos do 14º, 13º e 3º da fachada sul.

Sheet 1º MEDIÇÃO (2)
A1: CONTROLE DE MEDIÇÃO - BURJ LAVIE
A2: M² Total: | B2: =SUM(E5:E35) -> 1572.48 | C2: Medição Instalação Total: | D2: 140000 | E2: M² Realizado Acumulado: | F2: 152.88 | G2: Medição Acumulado: | H2: 12930.46 | J2: Medição Nº: | K2: 2
D3: 1043756.4 | E3: M² Realizado Atual: | F3: =SUM(F5:F36)-(F2) -> 189.27737 | G3: Medição Atual com Retenção: | H3: =SUM(J5:J36)-(H2) -> 16009.132
A4: Referência | B4: Tipologia | C4: Localização | D4: Quantidade | E4: Área Total M² | F4: Realizado M² | G4: Saldo M² | H4: Medição Contrato | I4: Medição Realizado Total | J4: Medição com Retenção de 5% | K4: Saldo Medição
A5: ='CONTROLE DE OBRA BURJ LAVIE'!A3 -> J05 - LOTE 1 | B5: ='CONTROLE DE OBRA BURJ LAVIE'!B3 -> Fachada pele de vidro entre vãos c/ 3 modulos em parte fixas e moveis lote 1 | C5: ='CONTROLE DE OBRA BURJ LAVIE'!C3 -> Pav. Tipo do 2º ao 14 | D5: ='PELE DE VIDRO'!U3 -> 47 | E5: =SUM('PELE DE VIDRO'!H3:H5) -> 786.24 | F5: ='CONTROLE DE OBRA BURJ LAVIE'!O3 -> 342.15737 | G5: =E5-F5 -> 444.08263 | H5: =E5/$B$2*$D$2 -> 70000 | I5: =F5/$B$2*$D$2 -> 30462.729 | J5: =(F5/$B$2*$D$2)*(95%) -> 28939.592 | K5: =H5-J5 -> 41060.408
A6: ='CONTROLE DE OBRA BURJ LAVIE'!A4 -> J05 - LOTE 2 | B6: ='CONTROLE DE OBRA BURJ LAVIE'!B4 -> Fachada pele de vidro entre vãos c/ 3 modulos em parte fixas e moveis lote 2 | C6: ='CONTROLE DE OBRA BURJ LAVIE'!C4 -> Pav. Tipo do 2º ao 14 | D6: ='PELE DE VIDRO'!U6 -> 0 | E6: =SUM('PELE DE VIDRO'!H4:H6) -> 786.24 | F6: ='CONTROLE DE OBRA BURJ LAVIE'!O4 -> 0 | G6: =E6-F6 -> 786.24 | H6: =E6/$B$2*$D$2 -> 70000 | I6: =F6/$B$2*$D$2 -> 0 | J6: =(F6/$B$2*$D$2)*(95%) -> 0 | K6: =H6-J6 -> 70000
F7: ='CONTROLE DE OBRA BURJ LAVIE'!O5 -> 0 | G7: =E7-F7 -> 0 | H7: =E7/$B$2*$D$2 -> 0 | I7: =F7/$B$2*$D$2 -> 0 | J7: =(F7/$B$2*$D$2)*(95%) -> 0 | K7: =H7-J7 -> 0
F8: ='CONTROLE DE OBRA BURJ LAVIE'!O6 -> 0 | G8: =E8-F8 -> 0 | H8: =E8/$B$2*$D$2 -> 0 | I8: =F8/$B$2*$D$2 -> 0 | J8: =(F8/$B$2*$D$2)*(95%) -> 0 | K8: =H8-J8 -> 0
F9: ='CONTROLE DE OBRA BURJ LAVIE'!O7 -> 0 | G9: =E9-F9 -> 0 | H9: =E9/$B$2*$D$2 -> 0 | I9: =F9/$B$2*$D$2 -> 0 | J9: =(F9/$B$2*$D$2)*(95%) -> 0 | K9: =H9-J9 -> 0
F10: ='CONTROLE DE OBRA BURJ LAVIE'!O8 -> 0 | G10: =E10-F10 -> 0 | H10: =E10/$B$2*$D$2 -> 0 | I10: =F10/$B$2*$D$2 -> 0 | J10: =(F10/$B$2*$D$2)*(95%) -> 0 | K10: =H10-J10 -> 0
F11: ='CONTROLE DE OBRA BURJ LAVIE'!O9 -> 0 | G11: =E11-F11 -> 0 | H11: =E11/$B$2*$D$2 -> 0 | I11: =F11/$B$2*$D$2 -> 0 | J11: =(F11/$B$2*$D$2)*(95%) -> 0 | K11: =H11-J11 -> 0
F12: ='CONTROLE DE OBRA BURJ LAVIE'!O10 -> 0 | G12: =E12-F12 -> 0 | H12: =E12/$B$2*$D$2 -> 0 | I12: =F12/$B$2*$D$2 -> 0 | J12: =(F12/$B$2*$D$2)*(95%) -> 0 | K12: =H12-J12 -> 0
F13: ='CONTROLE DE OBRA BURJ LAVIE'!O11 -> 0 | G13: =E13-F13 -> 0 | H13: =E13/$B$2*$D$2 -> 0 | I13: =F13/$B$2*$D$2 -> 0 | J13: =(F13/$B$2*$D$2)*(95%) -> 0 | K13: =H13-J13 -> 0
F14: ='CONTROLE DE OBRA BURJ LAVIE'!O12 -> 0 | G14: =E14-F14 -> 0 | H14: =E14/$B$2*$D$2 -> 0 | I14: =F14/$B$2*$D$2 -> 0 | J14: =(F14/$B$2*$D$2)*(95%) -> 0 | K14: =H14-J14 -> 0
F15: ='CONTROLE DE OBRA BURJ LAVIE'!O13 -> 0 | G15: =E15-F15 -> 0 | H15: =E15/$B$2*$D$2 -> 0 | I15: =F15/$B$2*$D$2 -> 0 | J15: =(F15/$B$2*$D$2)*(95%) -> 0 | K15: =H15-J15 -> 0
F16: ='CONTROLE DE OBRA BURJ LAVIE'!O14 -> 0 | G16: =E16-F16 -> 0 | H16: =E16/$B$2*$D$2 -> 0 | I16: =F16/$B$2*$D$2 -> 0 | J16: =(F16/$B$2*$D$2)*(95%) -> 0 | K16: =H16-J16 -> 0
F17: ='CONTROLE DE OBRA BURJ LAVIE'!O15 -> 0 | G17: =E17-F17 -> 0 | H17: =E17/$B$2*$D$2 -> 0 | I17: =F17/$B$2*$D$2 -> 0 | J17: =(F17/$B$2*$D$2)*(95%) -> 0 | K17: =H17-J17 -> 0
F18: ='CONTROLE DE OBRA BURJ LAVIE'!O16 -> 0 | G18: =E18-F18 -> 0 | H18: =E18/$B$2*$D$2 -> 0 | I18: =F18/$B$2*$D$2 -> 0 | J18: =(F18/$B$2*$D$2)*(95%) -> 0 | K18: =H18-J18 -> 0
... F35: ='CONTROLE DE OBRA BURJ LAVIE'!O33 -> 0 | G35: =E35-F35 -> 0 | H35: =E35/$B$2*$D$2 -> 0 | I35: =F35/$B$2*$D$2 -> 0 | J35: =(F35/$B$2*$D$2)*(95%) -> 0 | K35: =H35-J35 -> 0
E36: =SUM(E5:E35) -> 1572.48
A38: Considerações Medição
A39: Instalação de Pele de vidro entre vãos do 14º, 13º e 3º da fachada sul.

Sheet VALOR DO CONTRATO
A2: VALOR TOTAL DO CONTRATO | B2: 1750000
A3: Fachada em Pele de vidro Entre Vãos | B3: =B2 -> 1750000
B5: =SUM(B3:B3) -> 1750000

Sheet MEDIÇÃO OBRA BURJ LAVIE
A1: MATRIZ MEDIÇÃO DE INSTALAÇÕES - OBRA BURJ LAVIE
A5: ITEM | B5: LINHA | C5: TIPOLOGIA | D5: REFERÊNCIA | E5: QUANT | F5: MEDIDAS | H5: ÁREA UNIT (M²) | I5: ÁREA TOTAL (M²) | J5: VALOR M² UNIT | K5: VALOR M² TOTAL ITEM | L5: QUANT SALDO À MEDIR | M5: QUANT MEDIDO | N5: MEDIDAS | P5: ÁREA UNIT (M²) | Q5: ÁREA TOTAL (M²) | R5: VALOR M² UNIT | S5: VALOR M² TOTAL | T5: STATUS DE MEDIÇÃO
S6: ='VALOR DO CONTRATO'!B2 -> 1750000 | T6: MEDIÇÃO 01 | U6: MEDIÇÃO 02 | V6: MEDIÇÃO 03 | W6: MEDIÇÃO 04 | X6: MEDIÇÃO 05 | Y6: MEDIÇÃO 06 | Z6: MEDIÇÃO 07 | AA6: MEDIÇÃO 08 | AB6: MEDIÇÃO 09 | AC6: MEDIÇÃO 10 | AD6: MEDIÇÃO 11 | AE6: MEDIÇÃO 12 | AF6: MEDIÇÃO 13 | AG6: MEDIÇÃO 14 | AH6: MEDIÇÃO 15
S7: SALDO ACUMULADO | T7: DATA | U7: DATA | V7: DATA | W7: DATA | X7: DATA | Y7: DATA | Z7: DATA | AA7: DATA | AB7: DATA | AC7: DATA | AD7: DATA | AE7: DATA | AF7: DATA | AG7: DATA | AH7: DATA
S8: =S6-S100 -> 1750000 | T8: 45524
H9: =F9*G9/1 -> 0 | I9: =E9*H9 -> 0 | K9: =J9*I9 -> 0 | L9: =E9-M9 -> 0 | M9: =T9+U9+V9+W9+X9+Y9+Z9+AA9+AB9+AC9+AD9+AE9+AF9+AG9+AH9 -> 0 | P9: =N9*O9/1000000 -> 0 | Q9: =M9*P9 -> 0 | R9: =J9 -> 0 | S9: =Q9*R9 -> 0 | T9: 0 | U9: 0 | V9: 0 | W9: 0 | X9: 0 | Y9: 0 | Z9: 0 | AA9: 0 | AB9: 0 | AC9: 0 | AD9: 0 | AE9: 0 | AF9: 0 | AG9: 0 | AH9: 0
H10: =F10*G10/1 -> 0 | I10: =E10*H10 -> 0 | K10: =J10*I10 -> 0 | L10: =E10-M10 -> 0 | M10: =T10+U10+V10+W10+X10+Y10+Z10+AA10+AB10+AC10+AD10+AE10+AF10+AG10+AH10 -> 0 | P10: =N10*O10/1000000 -> 0 | Q10: =M10*P10 -> 0 | R10: =J10 -> 0 | S10: =Q10*R10 -> 0 | T10: 0 | U10: 0 | V10: 0 | W10: 0 | X10: 0 | Y10: 0 | Z10: 0 | AA10: 0 | AB10: 0 | AC10: 0 | AD10: 0 | AE10: 0 | AF10: 0 | AG10: 0 | AH10: 0
H11: =F11*G11/1 -> 0 | I11: =E11*H11 -> 0 | K11: =J11*I11 -> 0 | L11: =E11-M11 -> 0 | M11: =T11+U11+V11+W11+X11+Y11+Z11+AA11+AB11+AC11+AD11+AE11+AF11+AG11+AH11 -> 0 | P11: =N11*O11/1000000 -> 0 | Q11: =M11*P11 -> 0 | R11: =J11 -> 0 | S11: =Q11*R11 -> 0 | T11: 0 | U11: 0 | V11: 0 | W11: 0 | X11: 0 | Y11: 0 | Z11: 0 | AA11: 0 | AB11: 0 | AC11: 0 | AD11: 0 | AE11: 0 | AF11: 0 | AG11: 0 | AH11: 0
H12: =F12*G12/1 -> 0 | I12: =E12*H12 -> 0 | K12: =J12*I12 -> 0 | L12: =E12-M12 -> 0 | M12: =T12+U12+V12+W12+X12+Y12+Z12+AA12+AB12+AC12+AD12+AE12+AF12+AG12+AH12 -> 0 | P12: =N12*O12/1000000 -> 0 | Q12: =M12*P12 -> 0 | R12: =J12 -> 0 | S12: =Q12*R12 -> 0 | T12: 0 | U12: 0 | V12: 0 | W12: 0 | X12: 0 | Y12: 0 | Z12: 0 | AA12: 0 | AB12: 0 | AC12: 0 | AD12: 0 | AE12: 0 | AF12: 0 | AG12: 0 | AH12: 0
H13: =F13*G13/1 -> 0 | I13: =E13*H13 -> 0 | K13: =J13*I13 -> 0 | L13: =E13-M13 -> 0 | M13: =T13+U13+V13+W13+X13+Y13+Z13+AA13+AB13+AC13+AD13+AE13+AF13+AG13+AH13 -> 0 | P13: =N13*O13/1000000 -> 0 | Q13: =M13*P13 -> 0 | R13: =J13 -> 0 | S13: =Q13*R13 -> 0 | T13: 0 | U13: 0 | V13: 0 | W13: 0 | X13: 0 | Y13: 0 | Z13: 0 | AA13: 0 | AB13: 0 | AC13: 0 | AD13: 0 | AE13: 0 | AF13: 0 | AG13: 0 | AH13: 0
H14: =F14*G14/1 -> 0 | I14: =E14*H14 -> 0 | K14: =J14*I14 -> 0 | L14: =E14-M14 -> 0 | M14: =T14+U14+V14+W14+X14+Y14+Z14+AA14+AB14+AC14+AD14+AE14+AF14+AG14+AH14 -> 0 | P14: =N14*O14/1000000 -> 0 | Q14: =M14*P14 -> 0 | R14: =J14 -> 0 | S14: =Q14*R14 -> 0 | T14: 0 | U14: 0 | V14: 0 | W14: 0 | X14: 0 | Y14: 0 | Z14: 0 | AA14: 0 | AB14: 0 | AC14: 0 | AD14: 0 | AE14: 0 | AF14: 0 | AG14: 0 | AH14: 0
H15: =F15*G15/1 -> 0 | I15: =E15*H15 -> 0 | K15: =J15*I15 -> 0 | L15: =E15-M15 -> 0 | M15: =T15+U15+V15+W15+X15+Y15+Z15+AA15+AB15+AC15+AD15+AE15+AF15+AG15+AH15 -> 0 | P15: =N15*O15/1000000 -> 0 | Q15: =M15*P15 -> 0 | R15: =J15 -> 0 | S15: =Q15*R15 -> 0 | T15: 0 | U15: 0 | V15: 0 | W15: 0 | X15: 0 | Y15: 0 | Z15: 0 | AA15: 0 | AB15: 0 | AC15: 0 | AD15: 0 | AE15: 0 | AF15: 0 | AG15: 0 | AH15: 0
H16: =F16*G16/1 -> 0 | I16: =E16*H16 -> 0 | K16: =J16*I16 -> 0 | L16: =E16-M16 -> 0 | M16: =T16+U16+V16+W16+X16+Y16+Z16+AA16+AB16+AC16+AD16+AE16+AF16+AG16+AH16 -> 0 | P16: =N16*O16/1000000 -> 0 | Q16: =M16*P16 -> 0 | R16: =J16 -> 0 | S16: =Q16*R16 -> 0 | T16: 0 | U16: 0 | V16: 0 | W16: 0 | X16: 0 | Y16: 0 | Z16: 0 | AA16: 0 | AB16: 0 | AC16: 0 | AD16: 0 | AE16: 0 | AF16: 0 | AG16: 0 | AH16: 0
H17: =F17*G17/1 -> 0 | I17: =E17*H17 -> 0 | K17: =J17*I17 -> 0 | L17: =E17-M17 -> 0 | M17: =T17+U17+V17+W17+X17+Y17+Z17+AA17+AB17+AC17+AD17+AE17+AF17+AG17+AH17 -> 0 | P17: =N17*O17/1000000 -> 0 | Q17: =M17*P17 -> 0 | R17: =J17 -> 0 | S17: =Q17*R17 -> 0 | T17: 0 | U17: 0 | V17: 0 | W17: 0 | X17: 0 | Y17: 0 | Z17: 0 | AA17: 0 | AB17: 0 | AC17: 0 | AD17: 0 | AE17: 0 | AF17: 0 | AG17: 0 | AH17: 0
H18: =F18*G18/1 -> 0 | I18: =E18*H18 -> 0 | K18: =J18*I18 -> 0 | L18: =E18-M18 -> 0 | M18: =T18+U18+V18+W18+X18+Y18+Z18+AA18+AB18+AC18+AD18+AE18+AF18+AG18+AH18 -> 0 | P18: =N18*O18/1000000 -> 0 | Q18: =M18*P18 -> 0 | R18: =J18 -> 0 | S18: =Q18*R18 -> 0 | T18: 0 | U18: 0 | V18: 0 | W18: 0 | X18: 0 | Y18: 0 | Z18: 0 | AA18: 0 | AB18: 0 | AC18: 0 | AD18: 0 | AE18: 0 | AF18: 0 | AG18: 0 | AH18: 0
H19: =F19*G19/1 -> 0 | I19: =E19*H19 -> 0 | K19: =J19*I19 -> 0 | L19: =E19-M19 -> 0 | M19: =T19+U19+V19+W19+X19+Y19+Z19+AA19+AB19+AC19+AD19+AE19+AF19+AG19+AH19 -> 0 | P19: =N19*O19/1000000 -> 0 | Q19: =M19*P19 -> 0 | R19: =J19 -> 0 | S19: =Q19*R19 -> 0 | T19: 0 | U19: 0 | V19: 0 | W19: 0 | X19: 0 | Y19: 0 | Z19: 0 | AA19: 0 | AB19: 0 | AC19: 0 | AD19: 0 | AE19: 0 | AF19: 0 | AG19: 0 | AH19: 0
H20: =F20*G20/1 -> 0 | I20: =E20*H20 -> 0 | K20: =J20*I20 -> 0 | L20: =E20-M20 -> 0 | M20: =T20+U20+V20+W20+X20+Y20+Z20+AA20+AB20+AC20+AD20+AE20+AF20+AG20+AH20 -> 0 | P20: =N20*O20/1000000 -> 0 | Q20: =M20*P20 -> 0 | R20: =J20 -> 0 | S20: =Q20*R20 -> 0 | T20: 0 | U20: 0 | V20: 0 | W20: 0 | X20: 0 | Y20: 0 | Z20: 0 | AA20: 0 | AB20: 0 | AC20: 0 | AD20: 0 | AE20: 0 | AF20: 0 | AG20: 0 | AH20: 0
H21: =F21*G21/1000000 -> 0 | I21: =E21*H21 -> 0 | K21: =J21*I21 -> 0 | L21: =E21-M21 -> 0 | M21: =T21+U21+V21+W21+X21+Y21+Z21+AA21+AB21+AC21+AD21+AE21+AF21+AG21+AH21 -> 0 | P21: =N21*O21/1000000 -> 0 | Q21: =M21*P21 -> 0 | R21: =J21 -> 0 | S21: =Q21*R21 -> 0 | T21: 0 | U21: 0 | V21: 0 | W21: 0 | X21: 0 | Y21: 0 | Z21: 0 | AA21: 0 | AB21: 0 | AC21: 0 | AD21: 0 | AE21: 0 | AF21: 0 | AG21: 0 | AH21: 0
H22: =F22*G22/1000000 -> 0 | I22: =E22*H22 -> 0 | K22: =J22*I22 -> 0 | L22: =E22-M22 -> 0 | M22: =T22+U22+V22+W22+X22+Y22+Z22+AA22+AB22+AC22+AD22+AE22+AF22+AG22+AH22 -> 0 | P22: =N22*O22/1000000 -> 0 | Q22: =M22*P22 -> 0 | R22: =J22 -> 0 | S22: =Q22*R22 -> 0 | T22: 0 | U22: 0 | V22: 0 | W22: 0 | X22: 0 | Y22: 0 | Z22: 0 | AA22: 0 | AB22: 0 | AC22: 0 | AD22: 0 | AE22: 0 | AF22: 0 | AG22: 0 | AH22: 0
H23: =F23*G23/1000000 -> 0 | I23: =E23*H23 -> 0 | K23: =J23*I23 -> 0 | L23: =E23-M23 -> 0 | M23: =T23+U23+V23+W23+X23+Y23+Z23+AA23+AB23+AC23+AD23+AE23+AF23+AG23+AH23 -> 0 | P23: =N23*O23/1000000 -> 0 | Q23: =M23*P23 -> 0 | R23: =J23 -> 0 | S23: =Q23*R23 -> 0 | T23: 0 | U23: 0 | V23: 0 | W23: 0 | X23: 0 | Y23: 0 | Z23: 0 | AA23: 0 | AB23: 0 | AC23: 0 | AD23: 0 | AE23: 0 | AF23: 0 | AG23: 0 | AH23: 0
H24: =F24*G24/1000000 -> 0 | I24: =E24*H24 -> 0 | K24: =J24*I24 -> 0 | L24: =E24-M24 -> 0 | M24: =T24+U24+V24+W24+X24+Y24+Z24+AA24+AB24+AC24+AD24+AE24+AF24+AG24+AH24 -> 0 | P24: =N24*O24/1000000 -> 0 | Q24: =M24*P24 -> 0 | R24: =J24 -> 0 | S24: =Q24*R24 -> 0 | T24: 0 | U24: 0 | V24: 0 | W24: 0 | X24: 0 | Y24: 0 | Z24: 0 | AA24: 0 | AB24: 0 | AC24: 0 | AD24: 0 | AE24: 0 | AF24: 0 | AG24: 0 | AH24: 0
H25: =F25*G25/1000000 -> 0 | I25: =E25*H25 -> 0 | K25: =J25*I25 -> 0 | L25: =E25-M25 -> 0 | M25: =T25+U25+V25+W25+X25+Y25+Z25+AA25+AB25+AC25+AD25+AE25+AF25+AG25+AH25 -> 0 | P25: =N25*O25/1000000 -> 0 | Q25: =M25*P25 -> 0 | R25: =J25 -> 0 | S25: =Q25*R25 -> 0 | T25: 0 | U25: 0 | V25: 0 | W25: 0 | X25: 0 | Y25: 0 | Z25: 0 | AA25: 0 | AB25: 0 | AC25: 0 | AD25: 0 | AE25: 0 | AF25: 0 | AG25: 0 | AH25: 0
H26: =F26*G26/1000000 -> 0 | I26: =E26*H26 -> 0 | K26: =J26*I26 -> 0 | L26: =E26-M26 -> 0 | M26: =T26+U26+V26+W26+X26+Y26+Z26+AA26+AB26+AC26+AD26+AE26+AF26+AG26+AH26 -> 0 | P26: =N26*O26/1000000 -> 0 | Q26: =M26*P26 -> 0 | R26: =J26 -> 0 | S26: =Q26*R26 -> 0 | T26: 0 | U26: 0 | V26: 0 | W26: 0 | X26: 0 | Y26: 0 | Z26: 0 | AA26: 0 | AB26: 0 | AC26: 0 | AD26: 0 | AE26: 0 | AF26: 0 | AG26: 0 | AH26: 0
H27: =F27*G27/1000000 -> 0 | I27: =E27*H27 -> 0 | K27: =J27*I27 -> 0 | L27: =E27-M27 -> 0 | M27: =T27+U27+V27+W27+X27+Y27+Z27+AA27+AB27+AC27+AD27+AE27+AF27+AG27+AH27 -> 0 | P27: =N27*O27/1000000 -> 0 | Q27: =M27*P27 -> 0 | R27: =J27 -> 0 | S27: =Q27*R27 -> 0 | T27: 0 | U27: 0 | V27: 0 | W27: 0 | X27: 0 | Y27: 0 | Z27: 0 | AA27: 0 | AB27: 0 | AC27: 0 | AD27: 0 | AE27: 0 | AF27: 0 | AG27: 0 | AH27: 0
H28: =F28*G28/1000000 -> 0 | I28: =E28*H28 -> 0 | K28: =J28*I28 -> 0 | L28: =E28-M28 -> 0 | M28: =T28+U28+V28+W28+X28+Y28+Z28+AA28+AB28+AC28+AD28+AE28+AF28+AG28+AH28 -> 0 | P28: =N28*O28/1000000 -> 0 | Q28: =M28*P28 -> 0 | R28: =J28 -> 0 | S28: =Q28*R28 -> 0 | T28: 0 | U28: 0 | V28: 0 | W28: 0 | X28: 0 | Y28: 0 | Z28: 0 | AA28: 0 | AB28: 0 | AC28: 0 | AD28: 0 | AE28: 0 | AF28: 0 | AG28: 0 | AH28: 0
H29: =F29*G29/1000000 -> 0 | I29: =E29*H29 -> 0 | K29: =J29*I29 -> 0 | L29: =E29-M29 -> 0 | M29: =T29+U29+V29+W29+X29+Y29+Z29+AA29+AB29+AC29+AD29+AE29+AF29+AG29+AH29 -> 0 | P29: =N29*O29/1000000 -> 0 | Q29: =M29*P29 -> 0 | R29: =J29 -> 0 | S29: =Q29*R29 -> 0 | T29: 0 | U29: 0 | V29: 0 | W29: 0 | X29: 0 | Y29: 0 | Z29: 0 | AA29: 0 | AB29: 0 | AC29: 0 | AD29: 0 | AE29: 0 | AF29: 0 | AG29: 0 | AH29: 0
H30: =F30*G30/1000000 -> 0 | I30: =E30*H30 -> 0 | K30: =J30*I30 -> 0 | L30: =E30-M30 -> 0 | M30: =T30+U30+V30+W30+X30+Y30+Z30+AA30+AB30+AC30+AD30+AE30+AF30+AG30+AH30 -> 0 | P30: =N30*O30/1000000 -> 0 | Q30: =M30*P30 -> 0 | R30: =J30 -> 0 | S30: =Q30*R30 -> 0 | T30: 0 | U30: 0 | V30: 0 | W30: 0 | X30: 0 | Y30: 0 | Z30: 0 | AA30: 0 | AB30: 0 | AC30: 0 | AD30: 0 | AE30: 0 | AF30: 0 | AG30: 0 | AH30: 0
H31: =F31*G31/1000000 -> 0 | I31: =E31*H31 -> 0 | K31: =J31*I31 -> 0 | L31: =E31-M31 -> 0 | M31: =T31+U31+V31+W31+X31+Y31+Z31+AA31+AB31+AC31+AD31+AE31+AF31+AG31+AH31 -> 0 | P31: =N31*O31/1000000 -> 0 | Q31: =M31*P31 -> 0 | R31: =J31 -> 0 | S31: =Q31*R31 -> 0 | T31: 0 | U31: 0 | V31: 0 | W31: 0 | X31: 0 | Y31: 0 | Z31: 0 | AA31: 0 | AB31: 0 | AC31: 0 | AD31: 0 | AE31: 0 | AF31: 0 | AG31: 0 | AH31: 0
H32: =F32*G32/1000000 -> 0 | I32: =E32*H32 -> 0 | K32: =J32*I32 -> 0 | L32: =E32-M32 -> 0 | M32: =T32+U32+V32+W32+X32+Y32+Z32+AA32+AB32+AC32+AD32+AE32+AF32+AG32+AH32 -> 0 | P32: =N32*O32/1000000 -> 0 | Q32: =M32*P32 -> 0 | R32: =J32 -> 0 | S32: =Q32*R32 -> 0 | T32: 0 | U32: 0 | V32: 0 | W32: 0 | X32: 0 | Y32: 0 | Z32: 0 | AA32: 0 | AB32: 0 | AC32: 0 | AD32: 0 | AE32: 0 | AF32: 0 | AG32: 0 | AH32: 0
... H81: =F81*G81/1000000 -> 0 | I81: =E81*H81 -> 0 | K81: =J81*I81 -> 0 | L81: =E81-M81 -> 0 | M81: =T81+U81+V81+W81+X81+Y81+Z81+AA81+AB81+AC81+AD81+AE81+AF81+AG81+AH81 -> 0 | P81: =N81*O81/1000000 -> 0 | Q81: =M81*P81 -> 0 | R81: =J81 -> 0 | S81: =Q81*R81 -> 0 | T81: 0 | U81: 0 | V81: 0 | W81: 0 | X81: 0 | Y81: 0 | Z81: 0 | AA81: 0 | AB81: 0 | AC81: 0 | AD81: 0 | AE81: 0 | AF81: 0 | AG81: 0 | AH81: 0
H82: =F82*G82/1000000 -> 0 | I82: =E82*H82 -> 0 | K82: =J82*I82 -> 0 | L82: =E82-M82 -> 0 | M82: =T82+U82+V82+W82+X82+Y82+Z82+AA82+AB82+AC82+AD82+AE82+AF82+AG82+AH82 -> 0 | P82: =N82*O82/1000000 -> 0 | Q82: =M82*P82 -> 0 | R82: =J82 -> 0 | S82: =Q82*R82 -> 0 | U82: 0 | V82: 0 | W82: 0 | X82: 0 | Y82: 0 | Z82: 0 | AA82: 0 | AB82: 0 | AC82: 0 | AD82: 0 | AE82: 0 | AF82: 0 | AG82: 0 | AH82: 0
H83: =F83*G83/1000000 -> 0 | I83: =E83*H83 -> 0 | K83: =J83*I83 -> 0 | L83: =E83-M83 -> 0 | M83: =T83+U83+V83+W83+X83+Y83+Z83+AA83+AB83+AC83+AD83+AE83+AF83+AG83+AH83 -> 0 | P83: =N83*O83/1000000 -> 0 | Q83: =M83*P83 -> 0 | R83: =J83 -> 0 | S83: =Q83*R83 -> 0 | U83: 0 | V83: 0 | W83: 0 | X83: 0 | Y83: 0 | Z83: 0 | AA83: 0 | AB83: 0 | AC83: 0 | AD83: 0 | AE83: 0 | AF83: 0 | AG83: 0 | AH83: 0
H84: =F84*G84/1000000 -> 0 | I84: =E84*H84 -> 0 | K84: =J84*I84 -> 0 | L84: =E84-M84 -> 0 | M84: =T84+U84+V84+W84+X84+Y84+Z84+AA84+AB84+AC84+AD84+AE84+AF84+AG84+AH84 -> 0 | P84: =N84*O84/1000000 -> 0 | Q84: =M84*P84 -> 0 | R84: =J84 -> 0 | S84: =Q84*R84 -> 0 | U84: 0 | V84: 0 | W84: 0 | X84: 0 | Y84: 0 | Z84: 0 | AA84: 0 | AB84: 0 | AC84: 0 | AD84: 0 | AE84: 0 | AF84: 0 | AG84: 0 | AH84: 0
H85: =F85*G85/1000000 -> 0 | I85: =E85*H85 -> 0 | K85: =J85*I85 -> 0 | L85: =E85-M85 -> 0 | M85: =T85+U85+V85+W85+X85+Y85+Z85+AA85+AB85+AC85+AD85+AE85+AF85+AG85+AH85 -> 0 | P85: =N85*O85/1000000 -> 0 | Q85: =M85*P85 -> 0 | R85: =J85 -> 0 | S85: =Q85*R85 -> 0 | T85: 0 | U85: 0 | V85: 0 | W85: 0 | X85: 0 | Y85: 0 | Z85: 0 | AA85: 0 | AB85: 0 | AC85: 0 | AD85: 0 | AE85: 0 | AF85: 0 | AG85: 0 | AH85: 0
H86: =F86*G86/1000000 -> 0 | I86: =E86*H86 -> 0 | K86: =J86*I86 -> 0 | L86: =E86-M86 -> 0 | M86: =T86+U86+V86+W86+X86+Y86+Z86+AA86+AB86+AC86+AD86+AE86+AF86+AG86+AH86 -> 0 | P86: =N86*O86/1000000 -> 0 | Q86: =M86*P86 -> 0 | R86: =J86 -> 0 | S86: =Q86*R86 -> 0 | T86: 0 | U86: 0 | V86: 0 | W86: 0 | X86: 0 | Y86: 0 | Z86: 0 | AA86: 0 | AB86: 0 | AC86: 0 | AD86: 0 | AE86: 0 | AF86: 0 | AG86: 0 | AH86: 0
H87: =F87*G87/1000000 -> 0 | I87: =E87*H87 -> 0 | K87: =J87*I87 -> 0 | L87: =E87-M87 -> 0 | M87: =T87+U87+V87+W87+X87+Y87+Z87+AA87+AB87+AC87+AD87+AE87+AF87+AG87+AH87 -> 0 | P87: =N87*O87/1000000 -> 0 | Q87: =M87*P87 -> 0 | R87: =J87 -> 0 | S87: =Q87*R87 -> 0 | T87: 0 | U87: 0 | V87: 0 | W87: 0 | X87: 0 | Y87: 0 | Z87: 0 | AA87: 0 | AB87: 0 | AC87: 0 | AD87: 0 | AE87: 0 | AF87: 0 | AG87: 0 | AH87: 0
H88: =F88*G88/1000000 -> 0 | I88: =E88*H88 -> 0 | K88: =J88*I88 -> 0 | L88: =E88-M88 -> 0 | M88: =T88+U88+V88+W88+X88+Y88+Z88+AA88+AB88+AC88+AD88+AE88+AF88+AG88+AH88 -> 0 | P88: =N88*O88/1000000 -> 0 | Q88: =M88*P88 -> 0 | R88: =J88 -> 0 | S88: =Q88*R88 -> 0 | T88: 0 | U88: 0 | V88: 0 | W88: 0 | X88: 0 | Y88: 0 | Z88: 0 | AA88: 0 | AB88: 0 | AC88: 0 | AD88: 0 | AE88: 0 | AF88: 0 | AG88: 0 | AH88: 0
H89: =F89*G89/1000000 -> 0 | I89: =E89*H89 -> 0 | K89: =J89*I89 -> 0 | L89: =E89-M89 -> 0 | M89: =T89+U89+V89+W89+X89+Y89+Z89+AA89+AB89+AC89+AD89+AE89+AF89+AG89+AH89 -> 0 | P89: =N89*O89/1000000 -> 0 | Q89: =M89*P89 -> 0 | R89: =J89 -> 0 | S89: =Q89*R89 -> 0 | T89: 0 | U89: 0 | V89: 0 | W89: 0 | X89: 0 | Y89: 0 | Z89: 0 | AA89: 0 | AB89: 0 | AC89: 0 | AD89: 0 | AE89: 0 | AF89: 0 | AG89: 0 | AH89: 0
H90: =F90*G90/1000000 -> 0 | I90: =E90*H90 -> 0 | K90: =J90*I90 -> 0 | L90: =E90-M90 -> 0 | M90: =T90+U90+V90+W90+X90+Y90+Z90+AA90+AB90+AC90+AD90+AE90+AF90+AG90+AH90 -> 0 | P90: =N90*O90/1000000 -> 0 | Q90: =M90*P90 -> 0 | R90: =J90 -> 0 | S90: =Q90*R90 -> 0 | T90: 0 | U90: 0 | V90: 0 | W90: 0 | X90: 0 | Y90: 0 | Z90: 0 | AA90: 0 | AB90: 0 | AC90: 0 | AD90: 0 | AE90: 0 | AF90: 0 | AG90: 0 | AH90: 0
H91: =F91*G91/1000000 -> 0 | I91: =E91*H91 -> 0 | K91: =J91*I91 -> 0 | L91: =E91-M91 -> 0 | M91: =T91+U91+V91+W91+X91+Y91+Z91+AA91+AB91+AC91+AD91+AE91+AF91+AG91+AH91 -> 0 | P91: =N91*O91/1000000 -> 0 | Q91: =M91*P91 -> 0 | R91: =J91 -> 0 | S91: =Q91*R91 -> 0 | T91: 0 | U91: 0 | V91: 0 | W91: 0 | X91: 0 | Y91: 0 | Z91: 0 | AA91: 0 | AB91: 0 | AC91: 0 | AD91: 0 | AE91: 0 | AF91: 0 | AG91: 0 | AH91: 0
...
